/* This function wraps around asynchronous route handlers to catch errors
and pass them to the next error-handling middleware */
const asyncWrapper = (fn) => {
  return async (req, res, next) => {
    try {
      await fn(req, res, next)
    } catch (error) {
      next(error)
    }
  }
}

module.exports = asyncWrapper
